Workbook
Name SegmentaçãodeDados_Qual_o_seu_Setor?: #N/A

Sheet Dashboard

Sheet Explicação
A1: Item | B1: Descrição
A2: Explicação | B2: Nessa aba contém todas informações sobre o critério de cálculo dessa planilha, e também orientações de uso.
A3: Critérios de Probabilidade | B3: As informações dessa aba servem para realizar a análise qualitativa da probabilidade do risco por setor. Os critérios estão divididos entre freqência, histórico de risco e recursos.O psicólogo deverá fazer a análise através de entrevistas e observações baseando-se nos critérios apresentados, e depois determinar: 1 - Baixa / 2 Média / 3 Alta Probabilidade para cada setor e cada tópico de risco na aba resumo por tópico, na coluna "Média Probabilidade". SUGESTÃO: Copiar e colar a aba de critérios de probabilidade em outro arquivo de excel apra ter rascunhos para os diversos setores da empresa).
A4: Dados Do Forms | B4: Aqui deverão ser colados os dados da planilha do forms com as pontuações geradas do questionário. IMPORTANTE: Ter muita atenção na hora de colar, verificar se está no início de toda a planilha (Linhas e Colunas).
A5: Dashboard | B5: Aqui serão gerados os Gráficos com a determinação final da matriz de risco Por Setor, Gravidade por setor, e gravidade geral da empresa.
A6: Escala | B6: Nessa Aba é possível visualizar por setor a média (Simples) da gravidade das respostas, além de estar sendo feita a conversão dos valores das perguntas abertas e invertidas.
A7: Lógica Direta | B7: Quanto maior a resposta, maior o risco psicossocial (ex: 'Você sofre pressão excessiva?').
A8: Lógica Invertida | B8: Quanto maior a resposta, menor o risco psicossocial (ex: 'Você sente apoio da liderança?').
A9: Pontuação Corrigida | B9: Campo calculado automaticamente com base na lógica direta ou invertida.
A10: Gravidade | B10: Classificação do risco com base na Pontuação Corrigida: Alta (>=3), Média (=2), Baixa (<=1).
A11: Gravidade Num / Probabilidade Num | B11: Conversão de texto para número: Alta = 3, Média = 2, Baixa = 1. Usado para cálculo de médias.
A12: Resumo Por tópico | B12: A aba 'Resumo por Tópico' calcula automaticamente a média da gravidade de cada bloco de10 perguntas por tema. Classificações são geradas com base nos valores médios. Essa aba fará a classificação das médias, trazendo o resultado automático da média da GRAVIDADE das respostas, já convertidas por cada tópico (Fator de Risco psicossocial).
A13: Probabilidade | B13: A classificação da Probabilidade deve ser feita por cada setor. Ou seja, sempre que um setor for filtrado, é preciso inserir a probabilidade dele aqui para que os resultados não fiquem iguais.
B14: A probabilidade é Classificação da chance do risco ocorrer com base na Resposta Original: Alta (>=3), Média (=2), Baixa (<=1).
A15: Como são calculadas as médias de gravidade e probabilidade? | B15: As colunas 'Gravidade Num' da aba Escala contêm valores numéricos para cada resposta (Alta=3, Média=2, Baixa=1). A aba 'Resumo por Tópico' calcula a média desses valores a cada 03, 04 ou 5 perguntas de um mesmo tema, e fornece a média de Gravidade por Tópico e da probabilidade inserida pelo psicólogo.
A16: Análise e Avaliação | B16: A aba análise e avaliação trará de forma automática os dados (Média da Gravidade, Média da Probabilidade). do setor que estiver filtrado na aba resumo por tópico. E também trará de forma automática, o cruzamento da gravidade com a probabilidade conforme determina a matriz de risco da NR 01. Classificando o risco final do tópico e do setor em baixo, médio, alto ou crítico. A coluna fonte geradora do risco , também poderá ser alterada de acordo com a análise do Psicólogo.
A17: Identificação. | B17: Nessa parte o psicólogo deverá informar seu nome completo e CRP como responsável técnico pela avaliação. Em seguida, colocar os dados da empresa e do setor que está filtrado. Para salvar os dados o Psi deverá selecionar todo o quadro e salvar em PDF, ou imagem, com o nome do setor. Exemplo: (DRPS - Financeiro) Em seguida é só trocar o setor e os dados fazer um novo salvamento.
A18: Medida de Controle | B18: Nessa aba está o calendário proposto para ações que promovem a saúde mental e previne o adoecimento emocional decorrente dos riscos psicossociais avaliados. Também pode ser alterado pelo Psicólogo ao avaliar as necessidades da empresa.
A19: Monitoramento de Desempenho | B19: Sugestão para o monitoramento Contínuo do Risco.

Sheet Dados do Forms
C1: Media | D1: =SUBTOTAL(1,Tabela_2[01 - Você já presenciou ou sofreu comentários ofensivos, piadas ou insinuações inadequadas no ambiente de trabalho? (- Responda pensando se já presenciou ou sofreu esse tipo de situação no trabalho.)]) -> #DIV/0! | E1: =SUBTOTAL(1,Tabela_2[02 - Você se sente à vontade para relatar situações de assédio moral ou sexual na empresa sem medo de represálias? (-Responda se você se sente seguro(a) para relatar situações de assédio na empresa.)]) -> #DIV/0! | F1: =SUBTOTAL(1,Tabela_2[03 - Existe um canal seguro e sigiloso para denunciar assédio na empresa? (-Responda se a empresa oferece um meio seguro para denunciar assédio e outras situações)]) -> #DIV/0! | G1: =SUBTOTAL(1,Tabela_2[04 - Há casos conhecidos de assédio moral ou sexual que não foram devidamente investigados ou punidos? (- Responda se você percebe que situações de assédio não são tratadas corretamente.)]) -> #DIV/0! | H1: =SUBTOTAL(1,Tabela_2[05 - O RH e os gestores demonstram comprometimento real com a prevenção do assédio? (- Responda se você percebe que situações de assédio não são tratadas corretamente.)]) -> #DIV/0! | I1: =SUBTOTAL(1,Tabela_2[06 - Você sente que pode contar com seus colegas em momentos de dificuldade? (-Responda se você sente que pode contar com seus colegas quando precisa.)]) -> #DIV/0! | J1: =SUBTOTAL(1,Tabela_2[07 - Existe apoio da liderança para lidar com desafios relacionados ao trabalho? (Responda se seus gestores ajudam quando surgem dificuldades no trabalho.)]) -> #DIV/0! | K1: =SUBTOTAL(1,Tabela_2[08 - O RH está presente e atuante quando surgem conflitos ou dificuldades no trabalho? (Responda se o RH costuma apoiar quando há conflitos ou problemas.)]) -> #DIV/0! | L1: =SUBTOTAL(1,Tabela_2[09 - Os gestores promovem um ambiente saudável e respeitoso? (Responda como você avalia o comportamento dos gestores no dia a dia.)]) -> #DIV/0! | M1: =SUBTOTAL(1,Tabela_2[10 - Você sente que pode expressar suas dificuldades no trabalho sem ser julgado(a)? (Responda se você se sente à vontade para falar sobre dificuldades no trabalho.)]) -> #DIV/0! | N1: =SUBTOTAL(1,Tabela_2[11 - Mudanças organizacionais impactaram negativamente seu sentimento de segurança no trabalho? (Responda se mudanças na empresa afetaram sua sensação de segurança no trabalho.)]) -> #DIV/0! | O1: =SUBTOTAL(1,Tabela_2[12 - Há comunicação clara sobre mudanças que afetam a empresa ou os trabalhadores? (Responda se a empresa costuma explicar bem as mudanças que acontecem.)]) -> #DIV/0! | P1: =SUBTOTAL(1,Tabela_2[13 - Você já sentiu que seu emprego estava ameaçado sem explicações claras durante períodos de mudança? (Responda se já sentiu insegurança sobre seu emprego durante mudanças.)]) -> #DIV/0! | Q1: =SUBTOTAL(1,Tabela_2[14 - Existe transparência na comunicação da empresa durante processos de mudança? (Responda se as mudanças são comunicadas de forma clara e aberta.)]) -> #DIV/0! | R1: =SUBTOTAL(1,Tabela_2[15 - Você recebe instruções claras sobre suas responsabilidades no trabalho? (Responda se você entende bem quais são suas responsabilidades.)]) -> #DIV/0! | S1: =SUBTOTAL(1,Tabela_2[16 - A comunicação da empresa ajuda você a entender o que é esperado do seu trabalho? (Responda se a empresa deixa claro o que espera do seu trabalho.)]) -> #DIV/0! | T1: =SUBTOTAL(1,Tabela_2[17 - A comunicação entre equipes e setores contribui para a clareza das suas tarefas? (Responda se a comunicação entre áreas ajuda no seu trabalho.)]) -> #DIV/0! | U1: =SUBTOTAL(1,Tabela_2[18 - Você se sente confortável para pedir esclarecimentos quando não entende suas funções ou prioridades? (Responda se você se sente à vontade para perguntar quando não entende algo.)]) -> #DIV/0! | V1: =SUBTOTAL(1,Tabela_2[19 - Você sente que seu esforço e desempenho são reconhecidos pela liderança? (Responda se você se sente valorizado(a) pelo trabalho que realiza.)]) -> #DIV/0! | W1: =SUBTOTAL(1,Tabela_2[20 - Você recebe feedback construtivo sobre o seu trabalho com regularidade? (Responda se você recebe orientações ou retornos sobre seu trabalho.)]) -> #DIV/0! | X1: =SUBTOTAL(1,Tabela_2[21 - Com que Frequência Você já se sentiu desmotivado(a) por falta de reconhecimento no trabalho? (Responda se a falta de reconhecimento já te deixou desmotivado(a).]) -> #DIV/0! | Y1: =SUBTOTAL(1,Tabela_2[22 - Você tem liberdade para tomar decisões sobre como executar suas tarefas diárias? (Responda se você pode sugerir melhorias ou decidir como fazer suas tarefas.)]) -> #DIV/0! | Z1: =SUBTOTAL(1,Tabela_2[23 - A empresa confia na sua capacidade de organizar e gerenciar o próprio trabalho? (Responda se sente que a empresa confia na forma como você organiza seu trabalho.)]) -> #DIV/0! | AA1: =SUBTOTAL(1,Tabela_2[24 - Existe excesso de controle ou burocracia que interfere no seu desempenho? (Responda se regras ou controles atrapalham seu desempenho.)]) -> #DIV/0! | AB1: =SUBTOTAL(1,Tabela_2[25 - Existe excesso de supervisão que impacta negativamente na sua produtividade ou bem-estar?]) -> #DIV/0! | AC1: =SUBTOTAL(1,Tabela_2[26 - Você acha justas e claras as formas que a empresa usa para avaliar o seu trabalho? (Responda se as formas de avaliar seu trabalho são claras e justas.)]) -> #DIV/0! | AD1: =SUBTOTAL(1,Tabela_2[27 - Você sente que há igualdade no reconhecimento entre diferentes áreas ou equipes? (Responda se você percebe tratamento justo entre equipes ou setores.)]) -> #DIV/0! | AE1: =SUBTOTAL(1,Tabela_2[28 - Você sente que há transparência nas decisões de desligamento na empresa? (Responda se a empresa é clara quando ocorrem desligamentos.)]) -> #DIV/0! | AF1: =SUBTOTAL(1,Tabela_2[29 - Você já presenciou casos de demissões que considerasse injustas? (Responda se já presenciou demissões que considerou injustas.)]) -> #DIV/0! | AG1: =SUBTOTAL(1,Tabela_2[30 - Você já vivenciou ou presenciou alguma situação de violência grave no trabalho (como agressão física, ameaça séria ou ataque verbal intenso)?]) -> #DIV/0! | AH1: =SUBTOTAL(1,Tabela_2[31 - Você já passou por algum evento grave no trabalho (como acidente sério, situação de risco extremo ou episódio muito impactante)? Responda se já passou por situações muito graves ou perigosas no trabalho.]) -> #DIV/0! | AI1: =SUBTOTAL(1,Tabela_2[32 - Alguma situação vivida no trabalho já foi tão marcante que deixou medo, choque ou forte abalo emocional? (Responda se alguma situação no trabalho já te causou forte abalo emocional.)]) -> #DIV/0! | AJ1: =SUBTOTAL(1,Tabela_2[33 - Você sente que, na maior parte do tempo, tem pouco trabalho a realizar durante sua jornada? (Responda se costuma ter pouco trabalho durante sua jornada.)]) -> #DIV/0! | AK1: =SUBTOTAL(1,Tabela_2[34 - Você costuma ficar com tempo ocioso no trabalho por falta de tarefas ou demandas claras? (Responda se frequentemente fica sem tarefas para realizar.)]) -> #DIV/0! | AL1: =SUBTOTAL(1,Tabela_2[35 - Você sente que suas habilidades ou conhecimentos são pouco utilizados no seu trabalho? (Responda se sente que suas habilidades são pouco aproveitadas.)]) -> #DIV/0! | AM1: =SUBTOTAL(1,Tabela_2[36 - Seu trabalho costuma ser pouco desafiador ou repetitivo a ponto de gerar desânimo? (Responda se o trabalho é repetitivo ou desmotivador.)]) -> #DIV/0! | AN1: =SUBTOTAL(1,Tabela_2[37 - Você sente que sua carga de trabalho diária é maior do que consegue realizar dentro do horário normal? (Responda se a quantidade de trabalho é maior do que consegue realizar.)]) -> #DIV/0! | AO1: =SUBTOTAL(1,Tabela_2[38 - Você frequentemente precisa fazer horas extras ou levar trabalho para casa? (Responda se costuma trabalhar além do horário normal.)]) -> #DIV/0! | AP1: =SUBTOTAL(1,Tabela_2[39 - Você já teve sintomas físicos ou emocionais (como exaustão, ansiedade ou insônia) devido ao excesso de trabalho? (Responda se o excesso de trabalho já afetou sua saúde)]) -> #DIV/0! | AQ1: =SUBTOTAL(1,Tabela_2[40 - A equipe é dimensionada/dividida corretamente para a demanda/quantidade de trabalho existente? (Responda se a quantidade de pessoas é suficiente para a demanda.)]) -> #DIV/0! | AR1: =SUBTOTAL(1,Tabela_2[41 - Você já evitou colegas ou superiores por causa de desentendimentos frequentes? (Responda se já evitou colegas ou superiores por conflitos.)]) -> #DIV/0! | AS1: =SUBTOTAL(1,Tabela_2[42 - Você percebe rivalidade excessiva ou desnecessária entre colegas ou setores? (Responda se percebe disputas desnecessárias no trabalho.)]) -> #DIV/0! | AT1: =SUBTOTAL(1,Tabela_2[43 - Conflitos no trabalho costumam ser resolvidos de forma justa? (Responda se os conflitos costumam ser resolvidos de forma justa.)]) -> #DIV/0! | AU1: =SUBTOTAL(1,Tabela_2[44 - Você trabalha em condições (como turnos diferentes, trabalho externo ou distância física) que dificultam a comunicação no trabalho? (Responda se seu trabalho dificulta a comunicação com colegas ou líderes.)]) -> #DIV/0! | AV1: =SUBTOTAL(1,Tabela_2[45 - A distância física entre você e sua equipe ou liderança dificulta a troca de informações? (Responda se a distância atrapalha a troca de informações.)]) -> #DIV/0! | AW1: =SUBTOTAL(1,Tabela_2[46 - Você já teve dificuldade para receber informações importantes no momento certo por causa da organização do trabalho? (Responda se já recebeu informações importantes com atraso.)]) -> #DIV/0! | AX1: =SUBTOTAL(1,Tabela_2[47 - Você tem acesso fácil aos meios necessários para se comunicar com colegas e liderança durante o trabalho? (Responda se você tem meios adequados para se comunicar no trabalho.)]) -> #DIV/0! | AY1: =SUBTOTAL(1,Tabela_2[48 - Você trabalha grande parte do tempo de forma remota ou sozinho(a), com pouco contato presencial com colegas ou liderança? (Responda se você trabalha a maior parte do tempo sozinho(a) ou à distância.)]) -> #DIV/0! | AZ1: =SUBTOTAL(1,Tabela_2[49 - Você sente que o trabalho remoto ou isolado faz com que se sinta distante da equipe ou da empresa? (Responda se isso faz você se sentir distante da equipe ou da empresa.)]) -> #DIV/0! | BA1: =SUBTOTAL(1,Tabela_2[50 - Mesmo trabalhando de forma remota ou isolada, você sente que recebe apoio e acompanhamento adequados da empresa?(Responda se, mesmo à distância, você recebe apoio da empresa.)]) -> #DIV/0! | BB1: =SUBTOTAL(1,Tabela_2[Coluna1]) -> #DIV/0! | BC1: =SUBTOTAL(1,Tabela_2[Coluna2]) -> #DIV/0! | BD1: =SUBTOTAL(1,Tabela_2[Coluna3]) -> #DIV/0! | BE1: =SUBTOTAL(1,Tabela_2[Coluna4]) -> #DIV/0! | BF1: =SUBTOTAL(1,Tabela_2[Coluna5]) -> #DIV/0! | BG1: =SUBTOTAL(1,Tabela_2[Coluna6]) -> #DIV/0! | BH1: =SUBTOTAL(1,Tabela_2[Coluna7]) -> #DIV/0! | BI1: =SUBTOTAL(1,Tabela_2[Coluna8]) -> #DIV/0! | BJ1: =SUBTOTAL(1,Tabela_2[Coluna9]) -> #DIV/0! | BK1: =SUBTOTAL(1,Tabela_2[Coluna10]) -> #DIV/0! | BL1: =SUBTOTAL(1,Tabela_2[Coluna11]) -> #DIV/0! | BM1: =SUBTOTAL(1,Tabela_2[Coluna12]) -> #DIV/0! | BN1: =SUBTOTAL(1,Tabela_2[Coluna13]) -> #DIV/0! | BO1: =SUBTOTAL(1,Tabela_2[Coluna14]) -> #DIV/0! | BP1: =SUBTOTAL(1,Tabela_2[Coluna15]) -> #DIV/0! | BQ1: =SUBTOTAL(1,Tabela_2[Coluna16]) -> #DIV/0! | BR1: =SUBTOTAL(1,Tabela_2[Coluna17]) -> #DIV/0! | BS1: =SUBTOTAL(1,Tabela_2[Coluna18]) -> #DIV/0! | BT1: =SUBTOTAL(1,Tabela_2[Coluna19]) -> #DIV/0! | BU1: =SUBTOTAL(1,Tabela_2[Coluna20]) -> #DIV/0! | BV1: =SUBTOTAL(1,Tabela_2[Coluna21]) -> #DIV/0! | BW1: =SUBTOTAL(1,Tabela_2[Coluna22]) -> #DIV/0! | BX1: =SUBTOTAL(1,Tabela_2[Coluna23]) -> #DIV/0! | BY1: =SUBTOTAL(1,Tabela_2[Coluna24]) -> #DIV/0! | BZ1: =SUBTOTAL(1,Tabela_2[Coluna25]) -> #DIV/0! | CA1: =SUBTOTAL(1,Tabela_2[Coluna26]) -> #DIV/0! | CB1: =SUBTOTAL(1,Tabela_2[Coluna27]) -> #DIV/0! | CC1: =SUBTOTAL(1,Tabela_2[Coluna28]) -> #DIV/0! | CD1: =SUBTOTAL(1,Tabela_2[Coluna29]) -> #DIV/0! | CE1: =SUBTOTAL(1,Tabela_2[Coluna30]) -> #DIV/0! | CF1: =SUBTOTAL(1,Tabela_2[Coluna31]) -> #DIV/0! | CG1: =SUBTOTAL(1,Tabela_2[Coluna32]) -> #DIV/0! | CH1: =SUBTOTAL(1,Tabela_2[Coluna33]) -> #DIV/0! | CI1: =SUBTOTAL(1,Tabela_2[Coluna34]) -> #DIV/0! | CJ1: =SUBTOTAL(1,Tabela_2[Coluna35]) -> #DIV/0! | CK1: =SUBTOTAL(1,Tabela_2[Coluna36]) -> #DIV/0! | CL1: =SUBTOTAL(1,Tabela_2[Coluna37]) -> #DIV/0! | CM1: =SUBTOTAL(1,Tabela_2[Coluna38]) -> #DIV/0! | CN1: =SUBTOTAL(1,Tabela_2[Coluna39]) -> #DIV/0! | CO1: =SUBTOTAL(1,Tabela_2[Coluna40]) -> #DIV/0!
C2: Media geral | D2: =AVERAGE(Tabela_2[[#All],[01 - Você já presenciou ou sofreu comentários ofensivos, piadas ou insinuações inadequadas no ambiente de trabalho? (- Responda pensando se já presenciou ou sofreu esse tipo de situação no trabalho.)]]) -> #DIV/0! | E2: =AVERAGE(Tabela_2[[#All],[02 - Você se sente à vontade para relatar situações de assédio moral ou sexual na empresa sem medo de represálias? (-Responda se você se sente seguro(a) para relatar situações de assédio na empresa.)]]) -> #DIV/0! | F2: =AVERAGE(Tabela_2[[#All],[03 - Existe um canal seguro e sigiloso para denunciar assédio na empresa? (-Responda se a empresa oferece um meio seguro para denunciar assédio e outras situações)]]) -> #DIV/0! | G2: =AVERAGE(Tabela_2[[#All],[04 - Há casos conhecidos de assédio moral ou sexual que não foram devidamente investigados ou punidos? (- Responda se você percebe que situações de assédio não são tratadas corretamente.)]]) -> #DIV/0! | H2: =AVERAGE(Tabela_2[[#All],[05 - O RH e os gestores demonstram comprometimento real com a prevenção do assédio? (- Responda se você percebe que situações de assédio não são tratadas corretamente.)]]) -> #DIV/0! | I2: =AVERAGE(Tabela_2[[#All],[06 - Você sente que pode contar com seus colegas em momentos de dificuldade? (-Responda se você sente que pode contar com seus colegas quando precisa.)]]) -> #DIV/0! | J2: =AVERAGE(Tabela_2[[#All],[07 - Existe apoio da liderança para lidar com desafios relacionados ao trabalho? (Responda se seus gestores ajudam quando surgem dificuldades no trabalho.)]]) -> #DIV/0! | K2: =AVERAGE(Tabela_2[[#All],[08 - O RH está presente e atuante quando surgem conflitos ou dificuldades no trabalho? (Responda se o RH costuma apoiar quando há conflitos ou problemas.)]]) -> #DIV/0! | L2: =AVERAGE(Tabela_2[[#All],[09 - Os gestores promovem um ambiente saudável e respeitoso? (Responda como você avalia o comportamento dos gestores no dia a dia.)]]) -> #DIV/0! | M2: =AVERAGE(Tabela_2[[#All],[10 - Você sente que pode expressar suas dificuldades no trabalho sem ser julgado(a)? (Responda se você se sente à vontade para falar sobre dificuldades no trabalho.)]]) -> #DIV/0! | N2: =AVERAGE(Tabela_2[[#All],[11 - Mudanças organizacionais impactaram negativamente seu sentimento de segurança no trabalho? (Responda se mudanças na empresa afetaram sua sensação de segurança no trabalho.)]]) -> #DIV/0! | O2: =AVERAGE(Tabela_2[[#All],[12 - Há comunicação clara sobre mudanças que afetam a empresa ou os trabalhadores? (Responda se a empresa costuma explicar bem as mudanças que acontecem.)]]) -> #DIV/0! | P2: =AVERAGE(Tabela_2[[#All],[13 - Você já sentiu que seu emprego estava ameaçado sem explicações claras durante períodos de mudança? (Responda se já sentiu insegurança sobre seu emprego durante mudanças.)]]) -> #DIV/0! | Q2: =AVERAGE(Tabela_2[[#All],[14 - Existe transparência na comunicação da empresa durante processos de mudança? (Responda se as mudanças são comunicadas de forma clara e aberta.)]]) -> #DIV/0! | R2: =AVERAGE(Tabela_2[[#All],[15 - Você recebe instruções claras sobre suas responsabilidades no trabalho? (Responda se você entende bem quais são suas responsabilidades.)]]) -> #DIV/0! | S2: =AVERAGE(Tabela_2[[#All],[16 - A comunicação da empresa ajuda você a entender o que é esperado do seu trabalho? (Responda se a empresa deixa claro o que espera do seu trabalho.)]]) -> #DIV/0! | T2: =AVERAGE(Tabela_2[[#All],[17 - A comunicação entre equipes e setores contribui para a clareza das suas tarefas? (Responda se a comunicação entre áreas ajuda no seu trabalho.)]]) -> #DIV/0! | U2: =AVERAGE(Tabela_2[[#All],[18 - Você se sente confortável para pedir esclarecimentos quando não entende suas funções ou prioridades? (Responda se você se sente à vontade para perguntar quando não entende algo.)]]) -> #DIV/0! | V2: =AVERAGE(Tabela_2[[#All],[19 - Você sente que seu esforço e desempenho são reconhecidos pela liderança? (Responda se você se sente valorizado(a) pelo trabalho que realiza.)]]) -> #DIV/0! | W2: =AVERAGE(Tabela_2[[#All],[20 - Você recebe feedback construtivo sobre o seu trabalho com regularidade? (Responda se você recebe orientações ou retornos sobre seu trabalho.)]]) -> #DIV/0! | X2: =AVERAGE(Tabela_2[[#All],[21 - Com que Frequência Você já se sentiu desmotivado(a) por falta de reconhecimento no trabalho? (Responda se a falta de reconhecimento já te deixou desmotivado(a).]]) -> #DIV/0! | Y2: =AVERAGE(Tabela_2[[#All],[22 - Você tem liberdade para tomar decisões sobre como executar suas tarefas diárias? (Responda se você pode sugerir melhorias ou decidir como fazer suas tarefas.)]]) -> #DIV/0! | Z2: =AVERAGE(Tabela_2[[#All],[23 - A empresa confia na sua capacidade de organizar e gerenciar o próprio trabalho? (Responda se sente que a empresa confia na forma como você organiza seu trabalho.)]]) -> #DIV/0! | AA2: =AVERAGE(Tabela_2[[#All],[24 - Existe excesso de controle ou burocracia que interfere no seu desempenho? (Responda se regras ou controles atrapalham seu desempenho.)]]) -> #DIV/0! | AB2: =AVERAGE(Tabela_2[[#All],[25 - Existe excesso de supervisão que impacta negativamente na sua produtividade ou bem-estar?]]) -> #DIV/0! | AC2: =AVERAGE(Tabela_2[[#All],[26 - Você acha justas e claras as formas que a empresa usa para avaliar o seu trabalho? (Responda se as formas de avaliar seu trabalho são claras e justas.)]]) -> #DIV/0! | AD2: =AVERAGE(Tabela_2[[#All],[27 - Você sente que há igualdade no reconhecimento entre diferentes áreas ou equipes? (Responda se você percebe tratamento justo entre equipes ou setores.)]]) -> #DIV/0! | AE2: =AVERAGE(Tabela_2[[#All],[28 - Você sente que há transparência nas decisões de desligamento na empresa? (Responda se a empresa é clara quando ocorrem desligamentos.)]]) -> #DIV/0! | AF2: =AVERAGE(Tabela_2[[#All],[29 - Você já presenciou casos de demissões que considerasse injustas? (Responda se já presenciou demissões que considerou injustas.)]]) -> #DIV/0! | AG2: =AVERAGE(Tabela_2[[#All],[30 - Você já vivenciou ou presenciou alguma situação de violência grave no trabalho (como agressão física, ameaça séria ou ataque verbal intenso)?]]) -> #DIV/0! | AH2: =AVERAGE(Tabela_2[[#All],[31 - Você já passou por algum evento grave no trabalho (como acidente sério, situação de risco extremo ou episódio muito impactante)? Responda se já passou por situações muito graves ou perigosas no trabalho.]]) -> #DIV/0! | AI2: =AVERAGE(Tabela_2[[#All],[32 - Alguma situação vivida no trabalho já foi tão marcante que deixou medo, choque ou forte abalo emocional? (Responda se alguma situação no trabalho já te causou forte abalo emocional.)]]) -> #DIV/0! | AJ2: =AVERAGE(Tabela_2[[#All],[33 - Você sente que, na maior parte do tempo, tem pouco trabalho a realizar durante sua jornada? (Responda se costuma ter pouco trabalho durante sua jornada.)]]) -> #DIV/0! | AK2: =AVERAGE(Tabela_2[[#All],[34 - Você costuma ficar com tempo ocioso no trabalho por falta de tarefas ou demandas claras? (Responda se frequentemente fica sem tarefas para realizar.)]]) -> #DIV/0! | AL2: =AVERAGE(Tabela_2[[#All],[35 - Você sente que suas habilidades ou conhecimentos são pouco utilizados no seu trabalho? (Responda se sente que suas habilidades são pouco aproveitadas.)]]) -> #DIV/0! | AM2: =AVERAGE(Tabela_2[[#All],[36 - Seu trabalho costuma ser pouco desafiador ou repetitivo a ponto de gerar desânimo? (Responda se o trabalho é repetitivo ou desmotivador.)]]) -> #DIV/0! | AN2: =AVERAGE(Tabela_2[[#All],[37 - Você sente que sua carga de trabalho diária é maior do que consegue realizar dentro do horário normal? (Responda se a quantidade de trabalho é maior do que consegue realizar.)]]) -> #DIV/0! | AO2: =AVERAGE(Tabela_2[[#All],[38 - Você frequentemente precisa fazer horas extras ou levar trabalho para casa? (Responda se costuma trabalhar além do horário normal.)]]) -> #DIV/0! | AP2: =AVERAGE(Tabela_2[[#All],[39 - Você já teve sintomas físicos ou emocionais (como exaustão, ansiedade ou insônia) devido ao excesso de trabalho? (Responda se o excesso de trabalho já afetou sua saúde)]]) -> #DIV/0! | AQ2: =AVERAGE(Tabela_2[[#All],[40 - A equipe é dimensionada/dividida corretamente para a demanda/quantidade de trabalho existente? (Responda se a quantidade de pessoas é suficiente para a demanda.)]]) -> #DIV/0! | AR2: =AVERAGE(Tabela_2[[#All],[41 - Você já evitou colegas ou superiores por causa de desentendimentos frequentes? (Responda se já evitou colegas ou superiores por conflitos.)]]) -> #DIV/0! | AS2: =AVERAGE(Tabela_2[[#All],[42 - Você percebe rivalidade excessiva ou desnecessária entre colegas ou setores? (Responda se percebe disputas desnecessárias no trabalho.)]]) -> #DIV/0! | AT2: =AVERAGE(Tabela_2[[#All],[43 - Conflitos no trabalho costumam ser resolvidos de forma justa? (Responda se os conflitos costumam ser resolvidos de forma justa.)]]) -> #DIV/0! | AU2: =AVERAGE(Tabela_2[[#All],[44 - Você trabalha em condições (como turnos diferentes, trabalho externo ou distância física) que dificultam a comunicação no trabalho? (Responda se seu trabalho dificulta a comunicação com colegas ou líderes.)]]) -> #DIV/0! | AV2: =AVERAGE(Tabela_2[[#All],[45 - A distância física entre você e sua equipe ou liderança dificulta a troca de informações? (Responda se a distância atrapalha a troca de informações.)]]) -> #DIV/0! | AW2: =AVERAGE(Tabela_2[[#All],[46 - Você já teve dificuldade para receber informações importantes no momento certo por causa da organização do trabalho? (Responda se já recebeu informações importantes com atraso.)]]) -> #DIV/0! | AX2: =AVERAGE(Tabela_2[[#All],[47 - Você tem acesso fácil aos meios necessários para se comunicar com colegas e liderança durante o trabalho? (Responda se você tem meios adequados para se comunicar no trabalho.)]]) -> #DIV/0! | AY2: =AVERAGE(Tabela_2[[#All],[48 - Você trabalha grande parte do tempo de forma remota ou sozinho(a), com pouco contato presencial com colegas ou liderança? (Responda se você trabalha a maior parte do tempo sozinho(a) ou à distância.)]]) -> #DIV/0! | AZ2: =AVERAGE(Tabela_2[[#All],[49 - Você sente que o trabalho remoto ou isolado faz com que se sinta distante da equipe ou da empresa? (Responda se isso faz você se sentir distante da equipe ou da empresa.)]]) -> #DIV/0! | BA2: =AVERAGE(Tabela_2[[#All],[50 - Mesmo trabalhando de forma remota ou isolada, você sente que recebe apoio e acompanhamento adequados da empresa?(Responda se, mesmo à distância, você recebe apoio da empresa.)]]) -> #DIV/0! | BB2: =AVERAGE(Tabela_2[[#All],[Coluna1]]) -> #DIV/0! | BC2: =AVERAGE(Tabela_2[[#All],[Coluna2]]) -> #DIV/0! | BD2: =AVERAGE(Tabela_2[[#All],[Coluna3]]) -> #DIV/0! | BE2: =AVERAGE(Tabela_2[[#All],[Coluna4]]) -> #DIV/0! | BF2: =AVERAGE(Tabela_2[[#All],[Coluna5]]) -> #DIV/0! | BG2: =AVERAGE(Tabela_2[[#All],[Coluna6]]) -> #DIV/0! | BH2: =AVERAGE(Tabela_2[[#All],[Coluna7]]) -> #DIV/0! | BI2: =AVERAGE(Tabela_2[[#All],[Coluna8]]) -> #DIV/0! | BJ2: =AVERAGE(Tabela_2[[#All],[Coluna9]]) -> #DIV/0! | BK2: =AVERAGE(Tabela_2[[#All],[Coluna10]]) -> #DIV/0! | BL2: =AVERAGE(Tabela_2[[#All],[Coluna11]]) -> #DIV/0! | BM2: =AVERAGE(Tabela_2[[#All],[Coluna12]]) -> #DIV/0! | BN2: =AVERAGE(Tabela_2[[#All],[Coluna13]]) -> #DIV/0! | BO2: =AVERAGE(Tabela_2[[#All],[Coluna14]]) -> #DIV/0! | BP2: =AVERAGE(Tabela_2[[#All],[Coluna15]]) -> #DIV/0! | BQ2: =AVERAGE(Tabela_2[[#All],[Coluna16]]) -> #DIV/0! | BR2: =AVERAGE(Tabela_2[[#All],[Coluna17]]) -> #DIV/0! | BS2: =AVERAGE(Tabela_2[[#All],[Coluna18]]) -> #DIV/0! | BT2: =AVERAGE(Tabela_2[[#All],[Coluna19]]) -> #DIV/0! | BU2: =AVERAGE(Tabela_2[[#All],[Coluna20]]) -> #DIV/0! | BV2: =AVERAGE(Tabela_2[[#All],[Coluna21]]) -> #DIV/0! | BW2: =AVERAGE(Tabela_2[[#All],[Coluna22]]) -> #DIV/0! | BX2: =AVERAGE(Tabela_2[[#All],[Coluna23]]) -> #DIV/0! | BY2: =AVERAGE(Tabela_2[[#All],[Coluna24]]) -> #DIV/0! | BZ2: =AVERAGE(Tabela_2[[#All],[Coluna25]]) -> #DIV/0! | CA2: =AVERAGE(Tabela_2[[#All],[Coluna26]]) -> #DIV/0! | CB2: =AVERAGE(Tabela_2[[#All],[Coluna27]]) -> #DIV/0! | CC2: =AVERAGE(Tabela_2[[#All],[Coluna28]]) -> #DIV/0! | CD2: =AVERAGE(Tabela_2[[#All],[Coluna29]]) -> #DIV/0! | CE2: =AVERAGE(Tabela_2[[#All],[Coluna30]]) -> #DIV/0! | CF2: =AVERAGE(Tabela_2[[#All],[Coluna31]]) -> #DIV/0! | CG2: =AVERAGE(Tabela_2[[#All],[Coluna32]]) -> #DIV/0! | CH2: =AVERAGE(Tabela_2[[#All],[Coluna33]]) -> #DIV/0! | CI2: =AVERAGE(Tabela_2[[#All],[Coluna34]]) -> #DIV/0! | CJ2: =AVERAGE(Tabela_2[[#All],[Coluna35]]) -> #DIV/0! | CK2: =AVERAGE(Tabela_2[[#All],[Coluna36]]) -> #DIV/0! | CL2: =AVERAGE(Tabela_2[[#All],[Coluna37]]) -> #DIV/0! | CM2: =AVERAGE(Tabela_2[[#All],[Coluna38]]) -> #DIV/0! | CN2: =AVERAGE(Tabela_2[[#All],[Coluna39]]) -> #DIV/0! | CO2: =AVERAGE(Tabela_2[[#All],[Coluna40]]) -> #DIV/0!
M3: 1 | N3: 2 | W3: 2 | X3: 3 | AG3: 3 | AH3: 4 | AQ3: 4 | AR3: 5 | BA3: 5 | BB3: 6 | BK3: 6 | BL3: 7 | BU3: 7 | BV3: 8 | CE3: 8 | CF3: 9 | CO3: 9
A4: Carimbo de data/hora | B4: Qual o seu cargo/ Função? | C4: Qual o seu Setor? | D4: 01 - Você já presenciou ou sofreu comentários ofensivos, piadas ou insinuações inadequadas no ambiente de trabalho? (- Responda pensando se já presenciou ou sofreu esse tipo de situação no trabalho.) | E4: 02 - Você se sente à vontade para relatar situações de assédio moral ou sexual na empresa sem medo de represálias? (-Responda se você se sente seguro(a) para relatar situações de assédio na empresa.) | F4: 03 - Existe um canal seguro e sigiloso para denunciar assédio na empresa? (-Responda se a empresa oferece um meio seguro para denunciar assédio e outras situações) | G4: 04 - Há casos conhecidos de assédio moral ou sexual que não foram devidamente investigados ou punidos? (- Responda se você percebe que situações de assédio não são tratadas corretamente.) | H4: 05 - O RH e os gestores demonstram comprometimento real com a prevenção do assédio? (- Responda se você percebe que situações de assédio não são tratadas corretamente.) | I4: 06 - Você sente que pode contar com seus colegas em momentos de dificuldade? (-Responda se você sente que pode contar com seus colegas quando precisa.) | J4: 07 - Existe apoio da liderança para lidar com desafios relacionados ao trabalho? (Responda se seus gestores ajudam quando surgem dificuldades no trabalho.) | K4: 08 - O RH está presente e atuante quando surgem conflitos ou dificuldades no trabalho? (Responda se o RH costuma apoiar quando há conflitos ou problemas.) | L4: 09 - Os gestores promovem um ambiente saudável e respeitoso? (Responda como você avalia o comportamento dos gestores no dia a dia.) | M4: 10 - Você sente que pode expressar suas dificuldades no trabalho sem ser julgado(a)? (Responda se você se sente à vontade para falar sobre dificuldades no trabalho.) | N4: 11 - Mudanças organizacionais impactaram negativamente seu sentimento de segurança no trabalho? (Responda se mudanças na empresa afetaram sua sensação de segurança no trabalho.) | O4: 12 - Há comunicação clara sobre mudanças que afetam a empresa ou os trabalhadores? (Responda se a empresa costuma explicar bem as mudanças que acontecem.) | P4: 13 - Você já sentiu que seu emprego estava ameaçado sem explicações claras durante períodos de mudança? (Responda se já sentiu insegurança sobre seu emprego durante mudanças.) | Q4: 14 - Existe transparência na comunicação da empresa durante processos de mudança? (Responda se as mudanças são comunicadas de forma clara e aberta.) | R4: 15 - Você recebe instruções claras sobre suas responsabilidades no trabalho? (Responda se você entende bem quais são suas responsabilidades.) | S4: 16 - A comunicação da empresa ajuda você a entender o que é esperado do seu trabalho? (Responda se a empresa deixa claro o que espera do seu trabalho.) | T4: 17 - A comunicação entre equipes e setores contribui para a clareza das suas tarefas? (Responda se a comunicação entre áreas ajuda no seu trabalho.) | U4: 18 - Você se sente confortável para pedir esclarecimentos quando não entende suas funções ou prioridades? (Responda se você se sente à vontade para perguntar quando não entende algo.) | V4: 19 - Você sente que seu esforço e desempenho são reconhecidos pela liderança? (Responda se você se sente valorizado(a) pelo trabalho que realiza.) | W4: 20 - Você recebe feedback construtivo sobre o seu trabalho com regularidade? (Responda se você recebe orientações ou retornos sobre seu trabalho.) | X4: 21 - Com que Frequência Você já se sentiu desmotivado(a) por falta de reconhecimento no trabalho? (Responda se a falta de reconhecimento já te deixou desmotivado(a). | Y4: 22 - Você tem liberdade para tomar decisões sobre como executar suas tarefas diárias? (Responda se você pode sugerir melhorias ou decidir como fazer suas tarefas.) | Z4: 23 - A empresa confia na sua capacidade de organizar e gerenciar o próprio trabalho? (Responda se sente que a empresa confia na forma como você organiza seu trabalho.) | AA4: 24 - Existe excesso de controle ou burocracia que interfere no seu desempenho? (Responda se regras ou controles atrapalham seu desempenho.) | AB4: 25 - Existe excesso de supervisão que impacta negativamente na sua produtividade ou bem-estar? | AC4: 26 - Você acha justas e claras as formas que a empresa usa para avaliar o seu trabalho? (Responda se as formas de avaliar seu trabalho são claras e justas.) | AD4: 27 - Você sente que há igualdade no reconhecimento entre diferentes áreas ou equipes? (Responda se você percebe tratamento justo entre equipes ou setores.) | AE4: 28 - Você sente que há transparência nas decisões de desligamento na empresa? (Responda se a empresa é clara quando ocorrem desligamentos.) | AF4: 29 - Você já presenciou casos de demissões que considerasse injustas? (Responda se já presenciou demissões que considerou injustas.) | AG4: 30 - Você já vivenciou ou presenciou alguma situação de violência grave no trabalho (como agressão física, ameaça séria ou ataque verbal intenso)? | AH4: 31 - Você já passou por algum evento grave no trabalho (como acidente sério, situação de risco extremo ou episódio muito impactante)? Responda se já passou por situações muito graves ou perigosas no trabalho. | AI4: 32 - Alguma situação vivida no trabalho já foi tão marcante que deixou medo, choque ou forte abalo emocional? (Responda se alguma situação no trabalho já te causou forte abalo emocional.) | AJ4: 33 - Você sente que, na maior parte do tempo, tem pouco trabalho a realizar durante sua jornada? (Responda se costuma ter pouco trabalho durante sua jornada.) | AK4: 34 - Você costuma ficar com tempo ocioso no trabalho por falta de tarefas ou demandas claras? (Responda se frequentemente fica sem tarefas para realizar.) | AL4: 35 - Você sente que suas habilidades ou conhecimentos são pouco utilizados no seu trabalho? (Responda se sente que suas habilidades são pouco aproveitadas.) | AM4: 36 - Seu trabalho costuma ser pouco desafiador ou repetitivo a ponto de gerar desânimo? (Responda se o trabalho é repetitivo ou desmotivador.) | AN4: 37 - Você sente que sua carga de trabalho diária é maior do que consegue realizar dentro do horário normal? (Responda se a quantidade de trabalho é maior do que consegue realizar.) | AO4: 38 - Você frequentemente precisa fazer horas extras ou levar trabalho para casa? (Responda se costuma trabalhar além do horário normal.) | AP4: 39 - Você já teve sintomas físicos ou emocionais (como exaustão, ansiedade ou insônia) devido ao excesso de trabalho? (Responda se o excesso de trabalho já afetou sua saúde) | AQ4: 40 - A equipe é dimensionada/dividida corretamente para a demanda/quantidade de trabalho existente? (Responda se a quantidade de pessoas é suficiente para a demanda.) | AR4: 41 - Você já evitou colegas ou superiores por causa de desentendimentos frequentes? (Responda se já evitou colegas ou superiores por conflitos.) | AS4: 42 - Você percebe rivalidade excessiva ou desnecessária entre colegas ou setores? (Responda se percebe disputas desnecessárias no trabalho.) | AT4: 43 - Conflitos no trabalho costumam ser resolvidos de forma justa? (Responda se os conflitos costumam ser resolvidos de forma justa.) | AU4: 44 - Você trabalha em condições (como turnos diferentes, trabalho externo ou distância física) que dificultam a comunicação no trabalho? (Responda se seu trabalho dificulta a comunicação com colegas ou líderes.) | AV4: 45 - A distância física entre você e sua equipe ou liderança dificulta a troca de informações? (Responda se a distância atrapalha a troca de informações.) | AW4: 46 - Você já teve dificuldade para receber informações importantes no momento certo por causa da organização do trabalho? (Responda se já recebeu informações importantes com atraso.) | AX4: 47 - Você tem acesso fácil aos meios necessários para se comunicar com colegas e liderança durante o trabalho? (Responda se você tem meios adequados para se comunicar no trabalho.) | AY4: 48 - Você trabalha grande parte do tempo de forma remota ou sozinho(a), com pouco contato presencial com colegas ou liderança? (Responda se você trabalha a maior parte do tempo sozinho(a) ou à distância.) | AZ4: 49 - Você sente que o trabalho remoto ou isolado faz com que se sinta distante da equipe ou da empresa? (Responda se isso faz você se sentir distante da equipe ou da empresa.) | BA4: 50 - Mesmo trabalhando de forma remota ou isolada, você sente que recebe apoio e acompanhamento adequados da empresa?(Responda se, mesmo à distância, você recebe apoio da empresa.) | BB4: Coluna1 | BC4: Coluna2 | BD4: Coluna3 | BE4: Coluna4 | BF4: Coluna5 | BG4: Coluna6 | BH4: Coluna7 | BI4: Coluna8 | BJ4: Coluna9 | BK4: Coluna10 | BL4: Coluna11 | BM4: Coluna12 | BN4: Coluna13 | BO4: Coluna14 | BP4: Coluna15 | BQ4: Coluna16 | BR4: Coluna17 | BS4: Coluna18 | BT4: Coluna19 | BU4: Coluna20 | BV4: Coluna21 | BW4: Coluna22 | BX4: Coluna23 | BY4: Coluna24 | BZ4: Coluna25 | CA4: Coluna26 | CB4: Coluna27 | CC4: Coluna28 | CD4: Coluna29 | CE4: Coluna30 | CF4: Coluna31 | CG4: Coluna32 | CH4: Coluna33 | CI4: Coluna34 | CJ4: Coluna35 | CK4: Coluna36 | CL4: Coluna37 | CM4: Coluna38 | CN4: Coluna39 | CO4: Coluna40

Sheet Escala
D3: IMPORTANTE! | E3: Ao selecionar um setor ele Gerára em todas as abas os dados do setor.
D4: Lembre-se de Desmarcar Caso deseja ver os dados Gerais como um todo.
A7: Tópico | B7: Nº | C7: Pergunta | D7: Lógica | E7: MÉDIA | F7: Pontuação Corrigida | G7: Gravidade | H7: GravidadeNum
A8: Tópico 01 - Assédio de qualquer natureza no trabalho | B8: 1 | C8: Você já presenciou ou sofreu comentários ofensivos, piadas ou insinuações inadequadas no ambiente de trabalho? | D8: Direta | E8: =IFERROR(ROUNDUP('Dados do Forms'!D1,0),"") | F8: =IF(ISNUMBER(E8), IF(TRIM(UPPER(D8))="INVERTIDA", 4 - E8, E8), "") | G8: =IF(ISNUMBER(F8), IF(F8>=3,"Alta", IF(F8=2,"Média", IF(F8<=1,"Baixa",""))), "") | H8: =IF(G8="Alta",3,IF(G8="Média",2,IF(G8="Baixa",1,"")))
A9: Tópico 01 - Assédio de qualquer natureza no trabalho | B9: 2 | C9: Você se sente à vontade para relatar situações de assédio moral ou sexual na empresa sem medo de represálias? | D9: Invertida | E9: =IFERROR(ROUNDUP('Dados do Forms'!E1,0),"") | F9: =IF(ISNUMBER(E9), IF(TRIM(UPPER(D9))="INVERTIDA", 4 - E9, E9), "") | G9: =IF(ISNUMBER(F9), IF(F9>=3,"Alta", IF(F9=2,"Média", IF(F9<=1,"Baixa",""))), "") | H9: =IF(G9="Alta",3,IF(G9="Média",2,IF(G9="Baixa",1,"")))
A10: Tópico 01 - Assédio de qualquer natureza no trabalho | B10: 3 | C10: Existe um canal seguro e sigiloso para denunciar assédio na empresa? | D10: Invertida | E10: =IFERROR(ROUNDUP('Dados do Forms'!F1,0),"") | F10: =IF(ISNUMBER(E10), IF(D10="Invertida", 4 - E10, E10), "") | G10: =IF(ISNUMBER(F10), IF(F10>=3,"Alta", IF(F10=2,"Média", IF(F10<=1,"Baixa",""))), "") | H10: =IF(G10="Alta",3,IF(G10="Média",2,IF(G10="Baixa",1,"")))
A11: Tópico 01 - Assédio de qualquer natureza no trabalho | B11: 4 | C11: Há casos conhecidos de assédio moral ou sexual que não foram devidamente investigados ou punidos? | D11: Direta | E11: =IFERROR(ROUNDUP('Dados do Forms'!G1,0),"") | F11: =IF(ISNUMBER(E11), IF(D11="Invertida", 4 - E11, E11), "") | G11: =IF(ISNUMBER(F11), IF(F11>=3,"Alta", IF(F11=2,"Média", IF(F11<=1,"Baixa",""))), "") | H11: =IF(G11="Alta",3,IF(G11="Média",2,IF(G11="Baixa",1,"")))
A12: Tópico 01 - Assédio de qualquer natureza no trabalho | B12: 5 | C12: O RH e os gestores demonstram comprometimento real com a prevenção do assédio? | D12: Invertida | E12: =IFERROR(ROUNDUP('Dados do Forms'!H1,0),"") | F12: =IF(ISNUMBER(E12), IF(D12="Invertida", 4 - E12, E12), "") | G12: =IF(ISNUMBER(F12), IF(F12>=3,"Alta", IF(F12=2,"Média", IF(F12<=1,"Baixa",""))), "") | H12: =IF(G12="Alta",3,IF(G12="Média",2,IF(G12="Baixa",1,"")))
A13: Tópico 02 - Falta de suporte/apoio no trabalho | B13: 1 | C13: Você sente que pode contar com seus colegas em momentos de dificuldade? | D13: Invertida | E13: =IFERROR(ROUNDUP('Dados do Forms'!I1,0),"") | F13: =IF(ISNUMBER(E13), IF(D13="Invertida", 4 - E13, E13), "") | G13: =IF(ISNUMBER(F13), IF(F13>=3,"Alta", IF(F13=2,"Média", IF(F13<=1,"Baixa",""))), "") | H13: =IF(G13="Alta",3,IF(G13="Média",2,IF(G13="Baixa",1,"")))
A14: Tópico 02 - Falta de suporte/apoio no trabalho | B14: 2 | C14: Existe apoio da liderança para lidar com desafios relacionados ao trabalho? | D14: Invertida | E14: =IFERROR(ROUNDUP('Dados do Forms'!J1,0),"") | F14: =IF(ISNUMBER(E14), IF(D14="Invertida", 4 - E14, E14), "") | G14: =IF(ISNUMBER(F14), IF(F14>=3,"Alta", IF(F14=2,"Média", IF(F14<=1,"Baixa",""))), "") | H14: =IF(G14="Alta",3,IF(G14="Média",2,IF(G14="Baixa",1,"")))
A15: Tópico 02 - Falta de suporte/apoio no trabalho | B15: 3 | C15: O RH está presente e atuante quando surgem conflitos ou dificuldades no trabalho? | D15: Invertida | E15: =IFERROR(ROUNDUP('Dados do Forms'!K1,0),"") | F15: =IF(ISNUMBER(E15), IF(D15="Invertida", 4 - E15, E15), "") | G15: =IF(ISNUMBER(F15), IF(F15>=3,"Alta", IF(F15=2,"Média", IF(F15<=1,"Baixa",""))), "") | H15: =IF(G15="Alta",3,IF(G15="Média",2,IF(G15="Baixa",1,"")))
A16: Tópico 02 - Falta de suporte/apoio no trabalho | B16: 4 | C16: Os gestores promovem um ambiente saudável e respeitoso? | D16: Invertida | E16: =IFERROR(ROUNDUP('Dados do Forms'!L1,0),"") | F16: =IF(ISNUMBER(E16), IF(D16="Invertida", 4 - E16, E16), "") | G16: =IF(ISNUMBER(F16), IF(F16>=3,"Alta", IF(F16=2,"Média", IF(F16<=1,"Baixa",""))), "") | H16: =IF(G16="Alta",3,IF(G16="Média",2,IF(G16="Baixa",1,"")))
A17: Tópico 02 - Falta de suporte/apoio no trabalho | B17: 5 | C17: Você sente que pode expressar suas dificuldades no trabalho sem ser julgado(a)? | D17: Invertida | E17: =IFERROR(ROUNDUP('Dados do Forms'!M1,0),"") | F17: =IF(ISNUMBER(E17), IF(D17="Invertida", 4 - E17, E17), "") | G17: =IF(ISNUMBER(F17), IF(F17>=3,"Alta", IF(F17=2,"Média", IF(F17<=1,"Baixa",""))), "") | H17: =IF(G17="Alta",3,IF(G17="Média",2,IF(G17="Baixa",1,"")))
A18: Tópico 03 - Má gestão de mudanças organizacionais | B18: 1 | C18: Mudanças organizacionais impactaram negativamente seu sentimento de segurança no trabalho? | D18: Direta | E18: =IFERROR(ROUNDUP('Dados do Forms'!N1,0),"") | F18: =IF(ISNUMBER(E18), IF(D18="Invertida", 4 - E18, E18), "") | G18: =IF(ISNUMBER(F18), IF(F18>=3,"Alta", IF(F18=2,"Média", IF(F18<=1,"Baixa",""))), "") | H18: =IF(G18="Alta",3,IF(G18="Média",2,IF(G18="Baixa",1,"")))
A19: Tópico 03 - Má gestão de mudanças organizacionais | B19: 2 | C19: Há comunicação clara sobre mudanças que afetam a empresa ou os trabalhadores? | D19: Invertida | E19: =IFERROR(ROUNDUP('Dados do Forms'!O1,0),"") | F19: =IF(ISNUMBER(E19), IF(D19="Invertida", 4 - E19, E19), "") | G19: =IF(ISNUMBER(F19), IF(F19>=3,"Alta", IF(F19=2,"Média", IF(F19<=1,"Baixa",""))), "") | H19: =IF(G19="Alta",3,IF(G19="Média",2,IF(G19="Baixa",1,"")))
A20: Tópico 03 - Má gestão de mudanças organizacionais | B20: 3 | C20: Você já sentiu que seu emprego estava ameaçado sem explicações claras durante períodos de mudança? | D20: Direta | E20: =IFERROR(ROUNDUP('Dados do Forms'!P1,0),"") | F20: =IF(ISNUMBER(E20), IF(D20="Invertida", 4 - E20, E20), "") | G20: =IF(ISNUMBER(F20), IF(F20>=3,"Alta", IF(F20=2,"Média", IF(F20<=1,"Baixa",""))), "") | H20: =IF(G20="Alta",3,IF(G20="Média",2,IF(G20="Baixa",1,"")))
A21: Tópico 03 - Má gestão de mudanças organizacionais | B21: 4 | C21: Existe transparência na comunicação da empresa durante processos de mudança? | D21: Invertida | E21: =IFERROR(ROUNDUP('Dados do Forms'!Q1,0),"") | F21: =IF(ISNUMBER(E21), IF(D21="Invertida", 4 - E21, E21), "") | G21: =IF(ISNUMBER(F21), IF(F21>=3,"Alta", IF(F21=2,"Média", IF(F21<=1,"Baixa",""))), "") | H21: =IF(G21="Alta",3,IF(G21="Média",2,IF(G21="Baixa",1,"")))
A22: Tópico 04 - Baixa clareza de papel/função | B22: 1 | C22: Você recebe instruções claras sobre suas responsabilidades no trabalho? | D22: Invertida | E22: =IFERROR(ROUNDUP('Dados do Forms'!R1,0),"") | F22: =IF(ISNUMBER(E22), IF(D22="Invertida", 4 - E22, E22), "") | G22: =IF(ISNUMBER(F22), IF(F22>=3,"Alta", IF(F22=2,"Média", IF(F22<=1,"Baixa",""))), "") | H22: =IF(G22="Alta",3,IF(G22="Média",2,IF(G22="Baixa",1,"")))
A23: Tópico 04 - Baixa clareza de papel/função | B23: 2 | C23: A comunicação da empresa ajuda você a entender o que é esperado do seu trabalho? | D23: Invertida | E23: =IFERROR(ROUNDUP('Dados do Forms'!S1,0),"") | F23: =IF(ISNUMBER(E23), IF(D23="Invertida", 4 - E23, E23), "") | G23: =IF(ISNUMBER(F23), IF(F23>=3,"Alta", IF(F23=2,"Média", IF(F23<=1,"Baixa",""))), "") | H23: =IF(G23="Alta",3,IF(G23="Média",2,IF(G23="Baixa",1,"")))
A24: Tópico 04 - Baixa clareza de papel/função | B24: 3 | C24: A comunicação entre equipes e setores contribui para a clareza das suas tarefas? | D24: Invertida | E24: =IFERROR(ROUNDUP('Dados do Forms'!T1,0),"") | F24: =IF(ISNUMBER(E24), IF(D24="Invertida", 4 - E24, E24), "") | G24: =IF(ISNUMBER(F24), IF(F24>=3,"Alta", IF(F24=2,"Média", IF(F24<=1,"Baixa",""))), "") | H24: =IF(G24="Alta",3,IF(G24="Média",2,IF(G24="Baixa",1,"")))
A25: Tópico 04 - Baixa clareza de papel/função | B25: 4 | C25: Você se sente confortável para pedir esclarecimentos quando não entende suas funções ou prioridades? | D25: Invertida | E25: =IFERROR(ROUNDUP('Dados do Forms'!U1,0),"") | F25: =IF(ISNUMBER(E25), IF(D25="Invertida", 4 - E25, E25), "") | G25: =IF(ISNUMBER(F25), IF(F25>=3,"Alta", IF(F25=2,"Média", IF(F25<=1,"Baixa",""))), "") | H25: =IF(G25="Alta",3,IF(G25="Média",2,IF(G25="Baixa",1,"")))
A26: Tópico 05 - Baixas recompensas e reconhecimento | B26: 1 | C26: Você sente que seu esforço e desempenho são reconhecidos pela liderança? | D26: Invertida | E26: =IFERROR(ROUNDUP('Dados do Forms'!V1,0),"") | F26: =IF(ISNUMBER(E26), IF(D26="Invertida", 4 - E26, E26), "") | G26: =IF(ISNUMBER(F26), IF(F26>=3,"Alta", IF(F26=2,"Média", IF(F26<=1,"Baixa",""))), "") | H26: =IF(G26="Alta",3,IF(G26="Média",2,IF(G26="Baixa",1,"")))
A27: Tópico 05 - Baixas recompensas e reconhecimento | B27: 2 | C27: Você recebe feedback construtivo sobre o seu trabalho com regularidade? | D27: Invertida | E27: =IFERROR(ROUNDUP('Dados do Forms'!W1,0),"") | F27: =IF(ISNUMBER(E27), IF(D27="Invertida", 4 - E27, E27), "") | G27: =IF(ISNUMBER(F27), IF(F27>=3,"Alta", IF(F27=2,"Média", IF(F27<=1,"Baixa",""))), "") | H27: =IF(G27="Alta",3,IF(G27="Média",2,IF(G27="Baixa",1,"")))
A28: Tópico 05 - Baixas recompensas e reconhecimento | B28: 3 | C28: Você já se sentiu desmotivado(a) por falta de reconhecimento no trabalho? | D28: Direta | E28: =IFERROR(ROUNDUP('Dados do Forms'!X1,0),"") | F28: =IF(ISNUMBER(E28), IF(D28="Invertida", 4 - E28, E28), "") | G28: =IF(ISNUMBER(F28), IF(F28>=3,"Alta", IF(F28=2,"Média", IF(F28<=1,"Baixa",""))), "") | H28: =IF(G28="Alta",3,IF(G28="Média",2,IF(G28="Baixa",1,"")))
A29: Tópico 06 - Baixo controle no trabalho / Falta de autonomia | B29: 1 | C29: Você tem liberdade para tomar decisões sobre como executar suas tarefas diárias? | D29: Invertida | E29: =IFERROR(ROUNDUP('Dados do Forms'!Y1,0),"") | F29: =IF(ISNUMBER(E29), IF(D29="Invertida", 4 - E29, E29), "") | G29: =IF(ISNUMBER(F29), IF(F29>=3,"Alta", IF(F29=2,"Média", IF(F29<=1,"Baixa",""))), "") | H29: =IF(G29="Alta",3,IF(G29="Média",2,IF(G29="Baixa",1,"")))
A30: Tópico 06 - Baixo controle no trabalho / Falta de autonomia | B30: 2 | C30: A empresa confia na sua capacidade de organizar e gerenciar o próprio trabalho? | D30: Invertida | E30: =IFERROR(ROUNDUP('Dados do Forms'!Z1,0),"") | F30: =IF(ISNUMBER(E30), IF(D30="Invertida", 4 - E30, E30), "") | G30: =IF(ISNUMBER(F30), IF(F30>=3,"Alta", IF(F30=2,"Média", IF(F30<=1,"Baixa",""))), "") | H30: =IF(G30="Alta",3,IF(G30="Média",2,IF(G30="Baixa",1,"")))
A31: Tópico 06 - Baixo controle no trabalho / Falta de autonomia | B31: 3 | C31: O excesso de controle ou burocracia interfere no seu desempenho? | D31: Direta | E31: =IFERROR(ROUNDUP('Dados do Forms'!AA1,0),"") | F31: =IF(ISNUMBER(E31), IF(D31="Invertida", 4 - E31, E31), "") | G31: =IF(ISNUMBER(F31), IF(F31>=3,"Alta", IF(F31=2,"Média", IF(F31<=1,"Baixa",""))), "") | H31: =IF(G31="Alta",3,IF(G31="Média",2,IF(G31="Baixa",1,"")))
A32: Tópico 06 - Baixo controle no trabalho / Falta de autonomia | B32: 4 | C32: Existe excesso de supervisão que impacte negativamente sua produtividade ou bem-estar? | D32: Direta | E32: =IFERROR(ROUNDUP('Dados do Forms'!AB1,0),"") | F32: =IF(ISNUMBER(E32), IF(D32="Invertida", 4 - E32, E32), "") | G32: =IF(ISNUMBER(F32), IF(F32>=3,"Alta", IF(F32=2,"Média", IF(F32<=1,"Baixa",""))), "") | H32: =IF(G32="Alta",3,IF(G32="Média",2,IF(G32="Baixa",1,"")))
A33: Tópico 07 - Baixa justiça organizacional | B33: 1 | C33: Você acha justas e claras as formas que a empresa usa para avaliar o seu trabalho? | D33: Invertida | E33: =IFERROR(ROUNDUP('Dados do Forms'!AC1,0),"") | F33: =IF(ISNUMBER(E33), IF(D33="Invertida", 4 - E33, E33), "") | G33: =IF(ISNUMBER(F33), IF(F33>=3,"Alta", IF(F33=2,"Média", IF(F33<=1,"Baixa",""))), "") | H33: =IF(G33="Alta",3,IF(G33="Média",2,IF(G33="Baixa",1,"")))
A34: Tópico 07 - Baixa justiça organizacional | B34: 2 | C34: Você sente que há igualdade no reconhecimento entre diferentes áreas ou equipes? | D34: Invertida | E34: =IFERROR(ROUNDUP('Dados do Forms'!AD1,0),"") | F34: =IF(ISNUMBER(E34), IF(D34="Invertida", 4 - E34, E34), "") | G34: =IF(ISNUMBER(F34), IF(F34>=3,"Alta", IF(F34=2,"Média", IF(F34<=1,"Baixa",""))), "") | H34: =IF(G34="Alta",3,IF(G34="Média",2,IF(G34="Baixa",1,"")))
A35: Tópico 07 - Baixa justiça organizacional | B35: 3 | C35: Você sente que há transparência nas decisões de desligamento na empresa? | D35: Invertida | E35: =IFERROR(ROUNDUP('Dados do Forms'!AE1,0),"") | F35: =IF(ISNUMBER(E35), IF(D35="Invertida", 4 - E35, E35), "") | G35: =IF(ISNUMBER(F35), IF(F35>=3,"Alta", IF(F35=2,"Média", IF(F35<=1,"Baixa",""))), "") | H35: =IF(G35="Alta",3,IF(G35="Média",2,IF(G35="Baixa",1,"")))
A36: Tópico 07 - Baixa justiça organizacional | B36: 4 | C36: Você já presenciou casos de demissões injustas? | D36: Direta | E36: =IFERROR(ROUNDUP('Dados do Forms'!AF1,0),"") | F36: =IF(ISNUMBER(E36), IF(D36="Invertida", 4 - E36, E36), "") | G36: =IF(ISNUMBER(F36), IF(F36>=3,"Alta", IF(F36=2,"Média", IF(F36<=1,"Baixa",""))), "") | H36: =IF(G36="Alta",3,IF(G36="Média",2,IF(G36="Baixa",1,"")))
A37: Tópico 08 - Eventos violentos ou traumáticos | B37: 1 | C37: Você já vivenciou ou presenciou alguma situação de violência grave no trabalho (como agressão física, ameaça séria ou ataque verbal intenso)? | D37: Direta | E37: =IFERROR(ROUNDUP('Dados do Forms'!AG1,0),"") | F37: =IF(ISNUMBER(E37), IF(D37="Invertida", 4 - E37, E37), "") | G37: =IF(ISNUMBER(F37), IF(F37>=3,"Alta", IF(F37=2,"Média", IF(F37<=1,"Baixa",""))), "") | H37: =IF(G37="Alta",3,IF(G37="Média",2,IF(G37="Baixa",1,"")))
A38: Tópico 08 - Eventos violentos ou traumáticos | B38: 2 | C38: Você já passou por algum evento grave no trabalho (como acidente sério, situação de risco extremo ou episódio muito impactante)? | D38: Direta | E38: =IFERROR(ROUNDUP('Dados do Forms'!AH1,0),"") | F38: =IF(ISNUMBER(E38), IF(D38="Invertida", 4 - E38, E38), "") | G38: =IF(ISNUMBER(F38), IF(F38>=3,"Alta", IF(F38=2,"Média", IF(F38<=1,"Baixa",""))), "") | H38: =IF(G38="Alta",3,IF(G38="Média",2,IF(G38="Baixa",1,"")))
A39: Tópico 08 - Eventos violentos ou traumáticos | B39: 3 | C39: Alguma situação vivida no trabalho já foi tão marcante que deixou medo, choque ou forte abalo emocional? | D39: Direta | E39: =IFERROR(ROUNDUP('Dados do Forms'!AI1,0),"") | F39: =IF(ISNUMBER(E39), IF(D39="Invertida", 4 - E39, E39), "") | G39: =IF(ISNUMBER(F39), IF(F39>=3,"Alta", IF(F39=2,"Média", IF(F39<=1,"Baixa",""))), "") | H39: =IF(G39="Alta",3,IF(G39="Média",2,IF(G39="Baixa",1,"")))
A40: Tópico 09 - Baixa demanda no trabalho (Subcarga) | B40: 1 | C40: Você sente que, na maior parte do tempo, tem pouco trabalho a realizar durante sua jornada? | D40: Direta | E40: =IFERROR(ROUNDUP('Dados do Forms'!AJ1,0),"") | F40: =IF(ISNUMBER(E40), IF(D40="Invertida", 4 - E40, E40), "") | G40: =IF(ISNUMBER(F40), IF(F40>=3,"Alta", IF(F40=2,"Média", IF(F40<=1,"Baixa",""))), "") | H40: =IF(G40="Alta",3,IF(G40="Média",2,IF(G40="Baixa",1,"")))
A41: Tópico 09 - Baixa demanda no trabalho (Subcarga) | B41: 2 | C41: Você costuma ficar com tempo ocioso no trabalho por falta de tarefas ou demandas claras? | D41: Direta | E41: =IFERROR(ROUNDUP('Dados do Forms'!AK1,0),"") | F41: =IF(ISNUMBER(E41), IF(D41="Invertida", 4 - E41, E41), "") | G41: =IF(ISNUMBER(F41), IF(F41>=3,"Alta", IF(F41=2,"Média", IF(F41<=1,"Baixa",""))), "") | H41: =IF(G41="Alta",3,IF(G41="Média",2,IF(G41="Baixa",1,"")))
A42: Tópico 09 - Baixa demanda no trabalho (Subcarga) | B42: 3 | C42: Você sente que suas habilidades ou conhecimentos são pouco utilizados no seu trabalho? | D42: Direta | E42: =IFERROR(ROUNDUP('Dados do Forms'!AL1,0),"") | F42: =IF(ISNUMBER(E42), IF(D42="Invertida", 4 - E42, E42), "") | G42: =IF(ISNUMBER(F42), IF(F42>=3,"Alta", IF(F42=2,"Média", IF(F42<=1,"Baixa",""))), "") | H42: =IF(G42="Alta",3,IF(G42="Média",2,IF(G42="Baixa",1,"")))
A43: Tópico 09 - Baixa demanda no trabalho (Subcarga) | B43: 4 | C43: Seu trabalho costuma ser pouco desafiador ou repetitivo a ponto de gerar desânimo? | D43: Direta | E43: =IFERROR(ROUNDUP('Dados do Forms'!AM1,0),"") | F43: =IF(ISNUMBER(E43), IF(D43="Invertida", 4 - E43, E43), "") | G43: =IF(ISNUMBER(F43), IF(F43>=3,"Alta", IF(F43=2,"Média", IF(F43<=1,"Baixa",""))), "") | H43: =IF(G43="Alta",3,IF(G43="Média",2,IF(G43="Baixa",1,"")))
A44: Tópico 10 - Excesso de demandas no trabalho (Sobrecarga) | B44: 1 | C44: Você sente que sua carga de trabalho diária é maior do que consegue realizar dentro do horário normal? | D44: Direta | E44: =IFERROR(ROUNDUP('Dados do Forms'!AN1,0),"") | F44: =IF(ISNUMBER(E44), IF(D44="Invertida", 4 - E44, E44), "") | G44: =IF(ISNUMBER(F44), IF(F44>=3,"Alta", IF(F44=2,"Média", IF(F44<=1,"Baixa",""))), "") | H44: =IF(G44="Alta",3,IF(G44="Média",2,IF(G44="Baixa",1,"")))
...

Sheet Resumo por Tópico
D2: IMPORTANTE! | E2: Ao selecionar um setor ele Gerára em todas as abas os dados do setor.
D3: Lembre-se de Desmarcar Caso deseje ver os dados Gerais como um todo.
A7: Tópico | B7: Média Gravidade | C7: Média Probabilidade | D7: Classificação Gravidade | E7: Classificação Probabilidade
A8: Tópico 01 - Assédio de qualquer natureza no trabalho | B8: =AVERAGEIF(Escala!A:A, A8, Escala!H:H) -> #DIV/0! | D8: =IF(B8="", "", IFERROR(IF(B8<=1.66, "Baixa", IF(B8<=2.32, "Média", "Alta")), "")) -> #DIV/0! | E8: =IF(C8="","",IFERROR(IF(C8<=1.5,"Baixa",IF(C8<=2.4,"Média","Alta")),""))
A9: Tópico 02 - Falta de suporte/apoio no trabalho | B9: =AVERAGEIF(Escala!A:A, A9, Escala!H:H) -> #DIV/0! | D9: =IF(B9="", "", IFERROR(IF(B9<=1.66, "Baixa", IF(B9<=2.32, "Média", "Alta")), "")) -> #DIV/0! | E9: =IF(C9="","",IFERROR(IF(C9<=1.5,"Baixa",IF(C9<=2.4,"Média","Alta")),""))
A10: Tópico 03 - Má gestão de mudanças organizacionais | B10: =AVERAGEIF(Escala!A:A, A10, Escala!H:H) -> #DIV/0! | D10: =IF(B10="", "", IFERROR(IF(B10<=1.66, "Baixa", IF(B10<=2.32, "Média", "Alta")), "")) -> #DIV/0! | E10: =IF(C10="","",IFERROR(IF(C10<=1.5,"Baixa",IF(C10<=2.4,"Média","Alta")),""))
A11: Tópico 04 - Baixa clareza de papel/função | B11: =AVERAGEIF(Escala!A:A, A11, Escala!H:H) -> #DIV/0! | D11: =IF(B11="", "", IFERROR(IF(B11<=1.66, "Baixa", IF(B11<=2.32, "Média", "Alta")), "")) -> #DIV/0! | E11: =IF(C11="","",IFERROR(IF(C11<=1.5,"Baixa",IF(C11<=2.4,"Média","Alta")),""))
A12: Tópico 05 - Baixas recompensas e reconhecimento | B12: =AVERAGEIF(Escala!A:A, A12, Escala!H:H) -> #DIV/0! | D12: =IF(B12="", "", IFERROR(IF(B12<=1.66, "Baixa", IF(B12<=2.32, "Média", "Alta")), "")) -> #DIV/0! | E12: =IF(C12="","",IFERROR(IF(C12<=1.5,"Baixa",IF(C12<=2.4,"Média","Alta")),""))
A13: Tópico 06 - Baixo controle no trabalho / Falta de autonomia | B13: =AVERAGEIF(Escala!A:A, A13, Escala!H:H) -> #DIV/0! | D13: =IF(B13="", "", IFERROR(IF(B13<=1.66, "Baixa", IF(B13<=2.32, "Média", "Alta")), "")) -> #DIV/0! | E13: =IF(C13="","",IFERROR(IF(C13<=1.5,"Baixa",IF(C13<=2.4,"Média","Alta")),""))
A14: Tópico 07 - Baixa justiça organizacional | B14: =AVERAGEIF(Escala!A:A, A14, Escala!H:H) -> #DIV/0! | D14: =IF(B14="", "", IFERROR(IF(B14<=1.66, "Baixa", IF(B14<=2.32, "Média", "Alta")), "")) -> #DIV/0! | E14: =IF(C14="","",IFERROR(IF(C14<=1.5,"Baixa",IF(C14<=2.4,"Média","Alta")),""))
A15: Tópico 08 - Eventos violentos ou traumáticos | B15: =AVERAGEIF(Escala!A:A, A15, Escala!H:H) -> #DIV/0! | D15: =IF(B15="", "", IFERROR(IF(B15<=1.66, "Baixa", IF(B15<=2.32, "Média", "Alta")), "")) -> #DIV/0! | E15: =IF(C15="","",IFERROR(IF(C15<=1.5,"Baixa",IF(C15<=2.4,"Média","Alta")),""))
A16: Tópico 09 - Baixa demanda no trabalho (Subcarga) | B16: =AVERAGEIF(Escala!A:A, A16, Escala!H:H) -> #DIV/0! | D16: =IF(B16="", "", IFERROR(IF(B16<=1.66, "Baixa", IF(B16<=2.32, "Média", "Alta")), "")) -> #DIV/0! | E16: =IF(C16="","",IFERROR(IF(C16<=1.5,"Baixa",IF(C16<=2.4,"Média","Alta")),""))
A17: Tópico 10 - Excesso de demandas no trabalho (Sobrecarga) | B17: =AVERAGEIF(Escala!A:A, A17, Escala!H:H) -> #DIV/0! | D17: =IF(B17="", "", IFERROR(IF(B17<=1.66, "Baixa", IF(B17<=2.32, "Média", "Alta")), "")) -> #DIV/0! | E17: =IF(C17="","",IFERROR(IF(C17<=1.5,"Baixa",IF(C17<=2.4,"Média","Alta")),""))
A18: Tópico 11 - Maus relacionamentos no local de trabalho | B18: =AVERAGEIF(Escala!A:A, A18, Escala!H:H) -> #DIV/0! | D18: =IF(B18="", "", IFERROR(IF(B18<=1.66, "Baixa", IF(B18<=2.32, "Média", "Alta")), "")) -> #DIV/0! | E18: =IF(C18="","",IFERROR(IF(C18<=1.5,"Baixa",IF(C18<=2.4,"Média","Alta")),""))
A19: Tópico 12 - Trabalho em condições de difícil comunicação | B19: =AVERAGEIF(Escala!A:A, A19, Escala!H:H) -> #DIV/0! | D19: =IF(B19="", "", IFERROR(IF(B19<=1.66, "Baixa", IF(B19<=2.32, "Média", "Alta")), "")) -> #DIV/0! | E19: =IF(C19="","",IFERROR(IF(C19<=1.5,"Baixa",IF(C19<=2.4,"Média","Alta")),""))
A20: Tópico 13 - Trabalho remoto e isolado | B20: =AVERAGEIF(Escala!A:A, A20, Escala!H:H) -> #DIV/0! | D20: =IF(B20="", "", IFERROR(IF(B20<=1.66, "Baixa", IF(B20<=2.32, "Média", "Alta")), "")) -> #DIV/0! | E20: =IF(C20="","",IFERROR(IF(C20<=1.5,"Baixa",IF(C20<=2.4,"Média","Alta")),""))

Sheet Análise e Avaliação
C2: DRPS - DIAGNÓSTICO DE RISCOS PSICOSSOCIAIS
C3: Responsável Técnico pela Avaliação (Psicologo) (a): | F3: CRP:
C4: IDENTIFICAÇÃO
C5: CNPJ | D5: 00.000.000/0000-00 | F5: Data da Elaboração:
C6: Setor
C7: Funções | K7: Baixa | L7: Média | M7: Alta
C8: Quantidade de Trabalhadores na Função: | E8: Homens | F8: Mulheres | J8: Baixa | K8: Baixo | L8: Baixo | M8: Médio
